Workbook

Sheet ORIGINAL
A2: COMISIÓN DE BIOÉTICA DEL ESTADO DE TLAXCALA
A3: COMITÉS HOSPITALARIOS DE BIOÉTICA Y ÉTICA EN INVESTIGACIÓN
A4: CÉDULA DE VERIFICACIÓN
A5: Institución: | B5: Hospital General de Tlaxcala
A6: Responsable del establecimiento: | B6: ejemplo
A7: Presidente o presidenta: | B7: ejemplo
A8: Fecha de visita: | B8: ejemplo
A9: Registro CONBIOÉTICA: | B9: ejemplo
A10: CRITERIOS DE VERIFICACIÓN.
A11: I.- INTEGRACIÓN:
A12: Registro vigente ante la CONBIOÉTICA | C12: 1
A13: Acta de instalación actualizada y vigente | C13: 1
A14: Cartas de designación por cada integrante | C14: 1
A15: Cartas de confidencialidad por cada integrante | C15: 1
A16: Cartas compromiso de capacitación por integrante | C16: 1
A17: Mínimo de miembros necesarios: presidente, vocal secretario y cuatro vocales | C17: 1
A18: Cumple con no incluir personal del cuerpo directivo | C18: 1
A19: Su conformación es multidisciplinaria | C19: 1
A20: En la integración incluye representante de la comunidad | C20: 1
A21: Expedientes actualizados por cada integrante: CV, copia de título, cédula y constancias de capacitación en bioética | C21: 1
A22: Existe equidad de género en la integración del comité | C22: 1
A23: Se hace uso de lenguaje incluyente en la documentación | C23: 1
... A26: Los documentos se encuentra localizables, ordenados y resguardados | C26: 1
A27: SUBTOTAL POR DOMINIO: | C27: =SUM(C12:C26) -> 15
A28: II.- RECURSOS Y SUMINISTROS
A29: Cuenta con mecanismo de financiamiento para su operación | C29: 1
A30: Dispone de oficina para realizar actividades | C30: 1
A31: Cuenta con mobiliario y equipamiento para su funcionamiento | C31: 1
A32: Existen mecanismos para provisión de papeleria y demas insumos de oficina | C32: 1
A33: Dispone de un lugar para el resguardo de archivos o expedientes | C33: 1
A34: Cuenta con personal de apoyo administrativo | C34: 1
A35: SUBTOTAL POR DOMINIO: | C35: 6
A36: III.- MARCO PROCEDIMENTAL
A37: Cuenta con reglamento interno para el funcionamiento del comité | C37: 1
A38: Cuenta con manual de organización del comité | C38: 1
A39: Cuenta con procedimiento para la solicitud de intervención en el análisis de casos o protocolos | C39: 1
A40: Cuenta con procedimiento para control y seguimiento de recomendaciones emitidas por el comité | C40: 1
A41: Cuenta con procedimiento para resguardo de la información | C41: 1
A42: Cuenta con procedimiento para sesiones oridnarias y extraordinarias | C42: 1
A43: Cuenta con procedimiento para comunicar recomendaciones | C43: 1
...

Sheet CHBHdelaMujer
A2: COMISIÓN DE BIOÉTICA DEL ESTADO DE TLAXCALA
A3: COMITÉS HOSPITALARIOS DE BIOÉTICA Y ÉTICA EN INVESTIGACIÓN
A4: CÉDULA DE VERIFICACIÓN
A5: Institución: | B5: Hospital de la Mujer
A6: Responsable del establecimiento: | B6: Yahir Pasillas Pineda
A7: Presidente o presidenta: | B7: Susa Geraldine Moreno Medellin
A8: Fecha de visita: | B8: 45489
A9: Registro CONBIOÉTICA:
A10: CRITERIOS DE VERIFICACIÓN.
A11: I.- INTEGRACIÓN:
A12: Registro vigente ante la CONBIOÉTICA | C12: 0
A13: Acta de instalación actualizada y vigente | C13: 1
A14: Cartas de designación por cada integrante | C14: 1
A15: Cartas de confidencialidad por cada integrante | C15: 1
A16: Cartas compromiso de capacitación por integrante | C16: 1
A17: Mínimo de miembros necesarios: presidente, vocal secretario y cuatro vocales | C17: 1
A18: Cumple con no incluir personal del cuerpo directivo | C18: 1
A19: Su conformación es multidisciplinaria | C19: 1
A20: En la integración incluye representante de la comunidad | C20: 1
A21: Expedientes actualizados por cada integrante: CV, copia de título, cédula y constancias de capacitación en bioética | C21: 1
A22: Existe equidad de género en la integración del comité | C22: 0
A23: Se hace uso de lenguaje incluyente en la documentación | C23: 1
... A26: Los documentos se encuentra localizables, ordenados y resguardados | C26: 1
A27: SUBTOTAL POR DOMINIO: | C27: =SUM(C12:C26) -> 13
A28: II.- RECURSOS Y SUMINISTROS
A29: Cuenta con mecanismo de financiamiento para su operación | C29: 0
A30: Dispone de oficina para realizar actividades | C30: 0
A31: Cuenta con mobiliario y equipamiento para su funcionamiento | C31: 0
A32: Existen mecanismos para provisión de papeleria y demas insumos de oficina | C32: 0
A33: Dispone de un lugar para el resguardo de archivos o expedientes | C33: 0
A34: Cuenta con personal de apoyo administrativo | C34: 0
A35: SUBTOTAL POR DOMINIO: | C35: 0
A36: III.- MARCO PROCEDIMENTAL
A37: Cuenta con reglamento interno para el funcionamiento del comité | C37: 1
A38: Cuenta con manual de organización del comité | C38: 1
A39: Cuenta con procedimiento para la solicitud de intervención en el análisis de casos o protocolos | C39: 1
A40: Cuenta con procedimiento para control y seguimiento de recomendaciones emitidas por el comité | C40: 1
A41: Cuenta con procedimiento para resguardo de la información | C41: 1
A42: Cuenta con procedimiento para sesiones oridnarias y extraordinarias | C42: 1
A43: Cuenta con procedimiento para comunicar recomendaciones | C43: 1
...

Sheet CHBElCarmenT
A2: COMISIÓN DE BIOÉTICA DEL ESTADO DE TLAXCALA
A3: COMITÉS HOSPITALARIOS DE BIOÉTICA Y ÉTICA EN INVESTIGACIÓN
A4: CÉDULA DE VERIFICACIÓN
A5: Institución: | B5: Hospital Comunitario de el Carmen Tequexquital
A6: Responsable del establecimiento: | B6: Lic. Elizabeth Ceron Valencia
A7: Presidente o presidenta:
A8: Fecha de visita: | B8: 45628
A9: Registro CONBIOÉTICA: | B9: No
A10: CRITERIOS DE VERIFICACIÓN.
A11: I.- INTEGRACIÓN:
A12: Registro vigente ante la CONBIOÉTICA | C12: 0
A13: Acta de instalación actualizada y vigente | C13: 0
A14: Cartas de designación por cada integrante | C14: 0
A15: Cartas de confidencialidad por cada integrante | C15: 0
A16: Cartas compromiso de capacitación por integrante | C16: 0
A17: Mínimo de miembros necesarios: presidente, vocal secretario y cuatro vocales | C17: 0
A18: Cumple con no incluir personal del cuerpo directivo | C18: 0
A19: Su conformación es multidisciplinaria | C19: 0
A20: En la integración incluye representante de la comunidad | C20: 0
A21: Expedientes actualizados por cada integrante: CV, copia de título, cédula y constancias de capacitación en bioética | C21: 0
A22: Existe equidad de género en la integración del comité | C22: 0
A23: Se hace uso de lenguaje incluyente en la documentación | C23: 0
... A26: Los documentos se encuentra localizables, ordenados y resguardados | C26: 0
A27: SUBTOTAL POR DOMINIO: | C27: =SUM(C12:C26) -> 0
A28: II.- RECURSOS Y SUMINISTROS
A29: Cuenta con mecanismo de financiamiento para su operación | C29: 0
A30: Dispone de oficina para realizar actividades | C30: 0
A31: Cuenta con mobiliario y equipamiento para su funcionamiento | C31: 0
A32: Existen mecanismos para provisión de papeleria y demas insumos de oficina | C32: 0
A33: Dispone de un lugar para el resguardo de archivos o expedientes | C33: 0
A34: Cuenta con personal de apoyo administrativo | C34: 0
A35: SUBTOTAL POR DOMINIO: | C35: 0
A36: III.- MARCO PROCEDIMENTAL
A37: Cuenta con reglamento interno para el funcionamiento del comité | C37: 0
A38: Cuenta con manual de organización del comité | C38: 0
A39: Cuenta con procedimiento para la solicitud de intervención en el análisis de casos o protocolos | C39: 0
A40: Cuenta con procedimiento para control y seguimiento de recomendaciones emitidas por el comité | C40: 0
A41: Cuenta con procedimiento para resguardo de la información | C41: 0
A42: Cuenta con procedimiento para sesiones oridnarias y extraordinarias | C42: 0
A43: Cuenta con procedimiento para comunicar recomendaciones | C43: 0
...

Sheet CHBTlaxco
A2: COMISIÓN DE BIOÉTICA DEL ESTADO DE TLAXCALA
A3: COMITÉS HOSPITALARIOS DE BIOÉTICA Y ÉTICA EN INVESTIGACIÓN
A4: CÉDULA DE VERIFICACIÓN
A5: Institución: | B5: Hospital Comunitario de Tlaxco
A6: Responsable del establecimiento: | B6: Juan Carlos Alducin Reyez
A7: Presidente o presidenta: | B7: Rafael Enrique Ceron Vieyra
A8: Fecha de visita: | B8: 45615
A9: Registro CONBIOÉTICA: | B9: 29-1520160408
A10: CRITERIOS DE VERIFICACIÓN.
A11: I.- INTEGRACIÓN:
A12: Registro vigente ante la CONBIOÉTICA | C12: 1
A13: Acta de instalación actualizada y vigente | C13: 0
A14: Cartas de designación por cada integrante | C14: 1
A15: Cartas de confidencialidad por cada integrante | C15: 1
A16: Cartas compromiso de capacitación por integrante | C16: 0
A17: Mínimo de miembros necesarios: presidente, vocal secretario y cuatro vocales | C17: 0
A18: Cumple con no incluir personal del cuerpo directivo | C18: 1
A19: Su conformación es multidisciplinaria | C19: 1
A20: En la integración incluye representante de la comunidad | C20: 0
A21: Expedientes actualizados por cada integrante: CV, copia de título, cédula y constancias de capacitación en bioética | C21: 0
A22: Existe equidad de género en la integración del comité | C22: 0
A23: Se hace uso de lenguaje incluyente en la documentación | C23: 0
... A26: Los documentos se encuentra localizables, ordenados y resguardados | C26: 1
A27: SUBTOTAL POR DOMINIO: | C27: =SUM(C12:C26) -> 6
A28: II.- RECURSOS Y SUMINISTROS
A29: Cuenta con mecanismo de financiamiento para su operación | C29: 0
A30: Dispone de oficina para realizar actividades | C30: 0
A31: Cuenta con mobiliario y equipamiento para su funcionamiento | C31: 0
A32: Existen mecanismos para provisión de papeleria y demas insumos de oficina | C32: 0
A33: Dispone de un lugar para el resguardo de archivos o expedientes | C33: 0
A34: Cuenta con personal de apoyo administrativo | C34: 0
A35: SUBTOTAL POR DOMINIO: | C35: 0
A36: III.- MARCO PROCEDIMENTAL
A37: Cuenta con reglamento interno para el funcionamiento del comité | C37: 0
A38: Cuenta con manual de organización del comité | C38: 0
A39: Cuenta con procedimiento para la solicitud de intervención en el análisis de casos o protocolos | C39: 0
A40: Cuenta con procedimiento para control y seguimiento de recomendaciones emitidas por el comité | C40: 0
A41: Cuenta con procedimiento para resguardo de la información | C41: 0
A42: Cuenta con procedimiento para sesiones oridnarias y extraordinarias | C42: 0
A43: Cuenta con procedimiento para comunicar recomendaciones | C43: 0
...

Sheet CHBContla
A2: COMISIÓN DE BIOÉTICA DEL ESTADO DE TLAXCALA
A3: COMITÉS HOSPITALARIOS DE BIOÉTICA Y ÉTICA EN INVESTIGACIÓN
A4: CÉDULA DE VERIFICACIÓN
A5: Institución: | B5: Hospital Comunitario de Contla
A6: Responsable del establecimiento: | B6: Eva Xochitiotzi Bautista
A7: Presidente o presidenta: | B7: Oliva Salazar Morales
A8: Fecha de visita: | B8: 45611
A9: Registro CONBIOÉTICA: | B9: No
A10: CRITERIOS DE VERIFICACIÓN.
A11: I.- INTEGRACIÓN:
A12: Registro vigente ante la CONBIOÉTICA | C12: 0
A13: Acta de instalación actualizada y vigente | C13: 0
A14: Cartas de designación por cada integrante | C14: 0
A15: Cartas de confidencialidad por cada integrante | C15: 0
A16: Cartas compromiso de capacitación por integrante | C16: 0
A17: Mínimo de miembros necesarios: presidente, vocal secretario y cuatro vocales | C17: 0
A18: Cumple con no incluir personal del cuerpo directivo | C18: 0
A19: Su conformación es multidisciplinaria | C19: 0
A20: En la integración incluye representante de la comunidad | C20: 0
A21: Expedientes actualizados por cada integrante: CV, copia de título, cédula y constancias de capacitación en bioética | C21: 0
A22: Existe equidad de género en la integración del comité | C22: 0
A23: Se hace uso de lenguaje incluyente en la documentación | C23: 0
... A26: Los documentos se encuentra localizables, ordenados y resguardados | C26: 0
A27: SUBTOTAL POR DOMINIO: | C27: =SUM(C12:C26) -> 0
A28: II.- RECURSOS Y SUMINISTROS
A29: Cuenta con mecanismo de financiamiento para su operación | C29: 0
A30: Dispone de oficina para realizar actividades | C30: 0
A31: Cuenta con mobiliario y equipamiento para su funcionamiento | C31: 0
A32: Existen mecanismos para provisión de papeleria y demas insumos de oficina | C32: 0
A33: Dispone de un lugar para el resguardo de archivos o expedientes | C33: 0
A34: Cuenta con personal de apoyo administrativo | C34: 0
A35: SUBTOTAL POR DOMINIO: | C35: 0
A36: III.- MARCO PROCEDIMENTAL
A37: Cuenta con reglamento interno para el funcionamiento del comité | C37: 0
A38: Cuenta con manual de organización del comité | C38: 0
A39: Cuenta con procedimiento para la solicitud de intervención en el análisis de casos o protocolos | C39: 0
A40: Cuenta con procedimiento para control y seguimiento de recomendaciones emitidas por el comité | C40: 0
A41: Cuenta con procedimiento para resguardo de la información | C41: 0
A42: Cuenta con procedimiento para sesiones oridnarias y extraordinarias | C42: 0
A43: Cuenta con procedimiento para comunicar recomendaciones | C43: 0
...

Sheet CHBNativitas
A2: COMISIÓN DE BIOÉTICA DEL ESTADO DE TLAXCALA
A3: COMITÉS HOSPITALARIOS DE BIOÉTICA Y ÉTICA EN INVESTIGACIÓN
A4: CÉDULA DE VERIFICACIÓN
A5: Institución: | B5: Hospital General de Nativitas
A6: Responsable del establecimiento: | B6: Lessie Anghel Jimenez Arciniega
A7: Presidente o presidenta: | B7: Omar Jimenez Padilla
A8: Fecha de visita: | B8: 11/|10/2024
A9: Registro CONBIOÉTICA:
A10: CRITERIOS DE VERIFICACIÓN
A11: I.- INTEGRACIÓN:
A12: Registro vigente ante la CONBIOÉTICA | C12: 0
A13: Acta de instalacion actualizada y vigente | C13: 0
A14: Cartas de designación por cada integrante | C14: 1
A15: Cartas de confidencialidad por cada integrante | C15: 0
A16: Cartas compromiso de capacitación por integrante | C16: 1
A17: Mínimo de miembros necesarios: presidente, vocal secretario y cuatro vocales | C17: 1
A18: Cumple con no incluir personal del cuerpo directivo | C18: 1
A19: Su conformación es multidisciplinaria | C19: 1
A20: En la integración incluye representante de la comunidad | C20: 1
A21: Expedientes actualizados por cada integrante: CV, copia de título, cédula y constancias de capacitación en bioética | C21: 0
A22: Existe equidad de género en la integración del comité | C22: 1
A23: Se hace uso de lenguaje incluyente en la documentación | C23: 1
... A26: Los documentos se encuentra localizables, ordenados y resguardados | C26: 0
A27: SUBTOTAL POR DOMINIO: | C27: =SUM(C12:C26) -> 9
A28: II.- RECURSOS Y SUMINISTROS
A29: Cuenta con mecanismo de financiamiento para su operación | C29: 0
A30: Dispone de oficina para realizar actividades | C30: 0
A31: Cuenta con mobiliario y equipamiento para su funcionamiento | C31: 0
A32: Existen mecanismos para provisión de papeleria y demas insumos de oficina | C32: 1
A33: Dispone de un lugar para el resguardo de archivos o expedientes | C33: 1
A34: Cuenta con personal de apoyo administrativo | C34: 1
A35: SUBTOTAL POR DOMINIO: | C35: =SUM(C29:C34) -> 3
A36: III.- MARCO PROCEDIMENTAL
A37: Cuenta con reglamento interno para el funcionamiento del comité | C37: 0
A38: Cuenta con manual de organización del comité | C38: 0
A39: Cuenta con procedimiento para la solicitud de intervención en el análisis de casos o protocolos | C39: 0
A40: Cuenta con procedimiento para control y seguimiento de recomendaciones emitidas por el comité | C40: 0
A41: Cuenta con procedimiento para resguardo de la información | C41: 0
A42: Cuenta con procedimiento para sesiones oridnarias y extraordinarias | C42: 0
A43: Cuenta con procedimiento para comunicar recomendaciones | C43: 0
...

Sheet CHBHGSPM
A2: COMISIÓN DE BIOÉTICA DEL ESTADO DE TLAXCALA
A3: COMITÉS HOSPITALARIOS DE BIOÉTICA Y ÉTICA EN INVESTIGACIÓN
A4: CÉDULA DE VERIFICACIÓN
A5: Institución: | B5: Hospital General de San Pablo del Monte
A6: Responsable del establecimiento: | B6: Ivan Benjamin Ramos Corona
A7: Presidente o presidenta: | B7: Rocio Silvestre Ramirez
A8: Fecha de visita: | B8: 45537
A9: Registro CONBIOÉTICA:
A10: CRITERIOS DE VERIFICACIÓN
A11: I.- INTEGRACIÓN:
A12: Registro vigente ante la CONBIOÉTICA | C12: 1
A13: Acta de instalacion actualizada y vigente | C13: 1
A14: Cartas de designación por cada integrante | C14: 0
A15: Cartas de confidencialidad por cada integrante | C15: 0
A16: Cartas compromiso de capacitación por integrante | C16: 0
A17: Mínimo de miembros necesarios: presidente, vocal secretario y cuatro vocales | C17: 1
A18: Cumple con no incluir personal del cuerpo directivo | C18: 1
A19: Su conformación es multidisciplinaria | C19: 1
A20: En la integración incluye representante de la comunidad | C20: 1
A21: Expedientes actualizados por cada integrante: CV, copia de título, cédula y constancias de capacitación en bioética | C21: 0
A22: Existe equidad de género en la integración del comité | C22: 0
A23: Se hace uso de lenguaje incluyente en la documentación | C23: 0
... A26: Los documentos se encuentra localizables, ordenados y resguardados | C26: 1
A27: SUBTOTAL POR DOMINIO: | C27: =SUM(C12:C26) -> 7
A28: II.- RECURSOS Y SUMINISTROS
A29: Cuenta con mecanismo de financiamiento para su operación | C29: 0
A30: Dispone de oficina para realizar actividades | C30: 0
A31: Cuenta con mobiliario y equipamiento para su funcionamiento | C31: 0
A32: Existen mecanismos para provisión de papeleria y demas insumos de oficina | C32: 0
A33: Dispone de un lugar para el resguardo de archivos o expedientes | C33: 0
A34: Cuenta con personal de apoyo administrativo | C34: 0
A35: SUBTOTAL POR DOMINIO: | C35: =SUM(C29:C34) -> 0
A36: III.- MARCO PROCEDIMENTAL
A37: Cuenta con reglamento interno para el funcionamiento del comité | C37: 0
A38: Cuenta con manual de organización del comité | C38: 0
A39: Cuenta con procedimiento para la solicitud de intervención en el análisis de casos o protocolos | C39: 0
A40: Cuenta con procedimiento para control y seguimiento de recomendaciones emitidas por el comité | C40: 0
A41: Cuenta con procedimiento para resguardo de la información | C41: 0
A42: Cuenta con procedimiento para sesiones oridnarias y extraordinarias | C42: 0
A43: Cuenta con procedimiento para comunicar recomendaciones | C43: 0
...

Sheet CHBHCZ
A2: COMISIÓN DE BIOÉTICA DEL ESTADO DE TLAXCALA
A3: COMITÉS HOSPITALARIOS DE BIOÉTICA Y ÉTICA EN INVESTIGACIÓN
A4: CÉDULA DE VERIFICACIÓN
A5: Institución: | B5: Hospital Comunitario de Zacatelco
A6: Responsable del establecimiento: | B6: Jose Antonio Ruiz Cañizales
A7: Presidente o presidenta: | B7: Jenny Lima Martinez
A8: Fecha de visita: | B8: 45491
A9: Registro CONBIOÉTICA: | B9: COBIOETICA29CHB011820171023
A10: CRITERIOS DE VERIFICACIÓN
A11: I.- INTEGRACIÓN:
A12: Registro vigente ante la CONBIOÉTICA | C12: 1
A13: Acta de instalacion actualizada y vigente | C13: 0
A14: Cartas de designación por cada integrante | C14: 0
A15: Cartas de confidencialidad por cada integrante | C15: 0
A16: Cartas compromiso de capacitación por integrante | C16: 0
A17: Mínimo de miembros necesarios: presidente, vocal secretario y cuatro vocales | C17: 0
A18: Cumple con no incluir personal del cuerpo directivo | C18: 1
A19: Su conformación es multidisciplinaria | C19: 0
A20: En la integración incluye representante de la comunidad | C20: 0
A21: Expedientes actualizados por cada integrante: CV, copia de título, cédula y constancias de capacitación en bioética | C21: 1
A22: Existe equidad de género en la integración del comité | C22: 0
A23: Se hace uso de lenguaje incluyente en la documentación | C23: 0
... A26: Los documentos se encuentra localizables, ordenados y resguardados | C26: 1
A27: SUBTOTAL POR DOMINIO: | C27: =SUM(C12:C26) -> 6
A28: II.- RECURSOS Y SUMINISTROS
A29: Cuenta con mecanismo de financiamiento para su operación | C29: 0
A30: Dispone de oficina para realizar actividades | C30: 0
A31: Cuenta con mobiliario y equipamiento para su funcionamiento | C31: 0
A32: Existen mecanismos para provisión de papeleria y demas insumos de oficina | C32: 0
A33: Dispone de un lugar para el resguardo de archivos o expedientes | C33: 1
A34: Cuenta con personal de apoyo administrativo | C34: 0
A35: SUBTOTAL POR DOMINIO: | C35: =SUM(C29:C34) -> 1
A36: III.- MARCO PROCEDIMENTAL
A37: Cuenta con reglamento interno para el funcionamiento del comité | C37: 0
A38: Cuenta con manual de organización del comité | C38: 0
A39: Cuenta con procedimiento para la solicitud de intervención en el análisis de casos o protocolos | C39: 0
A40: Cuenta con procedimiento para control y seguimiento de recomendaciones emitidas por el comité | C40: 0
A41: Cuenta con procedimiento para resguardo de la información | C41: 0
A42: Cuenta con procedimiento para sesiones oridnarias y extraordinarias | C42: 0
A43: Cuenta con procedimiento para comunicar recomendaciones | C43: 0
...

Sheet CHBIMSSZ8
A2: COMISIÓN DE BIOÉTICA DEL ESTADO DE TLAXCALA
A3: COMITÉS HOSPITALARIOS DE BIOÉTICA Y ÉTICA EN INVESTIGACIÓN
A4: CÉDULA DE VERIFICACIÓN
A5: Institución: | B5: Hospital General de Zona #8 IMSS
A6: Responsable del establecimiento: | B6: Dra. Rosalba Rodriguez Ávila
A7: Presidente o presidenta: | B7: Dra. Zitlali Portillo García
A8: Fecha de visita: | B8: 45468
A9: Registro CONBIOÉTICA: | B9: COBIOÉTICA-CHB-01220140606
A10: CRITERIOS DE VERIFICACIÓN
A11: I.- INTEGRACIÓN:
A12: Registro vigente ante la CONBIOÉTICA | C12: 1
A13: Acta de instalacion actualizada y vigente | C13: 1
A14: Cartas de designación por cada integrante | C14: 1
A15: Cartas de confidencialidad por cada integrante | C15: 1
A16: Cartas compromiso de capacitación por integrante | C16: 1
A17: Mínimo de miembros necesarios: presidente, vocal secretario y cuatro vocales | C17: 1
A18: Cumple con no incluir personal del cuerpo directivo | C18: 1
A19: Su conformación es multidisciplinaria | C19: 0
A20: En la integración incluye representante de la comunidad | C20: 0
A21: Expedientes actualizados por cada integrante: CV, copia de título, cédula y constancias de capacitación en bioética | C21: 1
A22: Existe equidad de género en la integración del comité | C22: 0
A23: Se hace uso de lenguaje incluyente en la documentación | C23: 0
... A26: Los documentos se encuentra localizables, ordenados y resguardados | C26: 0
A27: SUBTOTAL POR DOMINIO: | C27: =SUM(C12:C26) -> 10
A28: II.- RECURSOS Y SUMINISTROS
A29: Cuenta con mecanismo de financiamiento para su operación | C29: 0
A30: Dispone de oficina para realizar actividades | C30: 0
A31: Cuenta con mobiliario y equipamiento para su funcionamiento | C31: 0
A32: Existen mecanismos para provisión de papeleria y demas insumos de oficina | C32: 0
A33: Dispone de un lugar para el resguardo de archivos o expedientes | C33: 0
A34: Cuenta con personal de apoyo administrativo | C34: 0
A35: SUBTOTAL POR DOMINIO: | C35: =SUM(C29:C34) -> 0
A36: III.- MARCO PROCEDIMENTAL
A37: Cuenta con reglamento interno para el funcionamiento del comité | C37: 1
A38: Cuenta con manual de organización del comité | C38: 1
A39: Cuenta con procedimiento para la solicitud de intervención en el análisis de casos o protocolos | C39: 1
A40: Cuenta con procedimiento para control y seguimiento de recomendaciones emitidas por el comité | C40: 1
A41: Cuenta con procedimiento para resguardo de la información | C41: 0
A42: Cuenta con procedimiento para sesiones oridnarias y extraordinarias | C42: 1
A43: Cuenta con procedimiento para comunicar recomendaciones | C43: 1
...

Sheet CHBIMSSZ1
A2: COMISIÓN DE BIOÉTICA DEL ESTADO DE TLAXCALA
A3: COMITÉS HOSPITALARIOS DE BIOÉTICA Y ÉTICA EN INVESTIGACIÓN
A4: CÉDULA DE VERIFICACIÓN
A5: Institución: | B5: Hospital General de zona #1 IMSS
A6: Responsable del establecimiento: | B6: Dra. Karla Mendiola Ramirez
A7: Presidente o presidenta: | B7: Dr. Jose Luis Carmona Rodriguez
A8: Fecha de visita: | B8: 45462
A9: Registro CONBIOÉTICA: | B9: CONBIOÉTICA29CHB011320150604
A10: CRITERIOS DE VERIFICACIÓN
A11: I.- INTEGRACIÓN:
A12: Registro vigente ante la CONBIOÉTICA | C12: 1
A13: Acta de instalacion actualizada y vigente | C13: 0
A14: Cartas de designación por cada integrante | C14: 1
A15: Cartas de confidencialidad por cada integrante | C15: 0
A16: Cartas compromiso de capacitación por integrante | C16: 0
A17: Mínimo de miembros necesarios: presidente, vocal secretario y cuatro vocales | C17: 1
A18: Cumple con no incluir personal del cuerpo directivo | C18: 1
A19: Su conformación es multidisciplinaria | C19: 1
A20: En la integración incluye representante de la comunidad | C20: 1
A21: Expedientes actualizados por cada integrante: CV, copia de título, cédula y constancias de capacitación en bioética | C21: 0
A22: Existe equidad de género en la integración del comité | C22: 0
A23: Se hace uso de lenguaje incluyente en la documentación | C23: 0
... A26: Los documentos se encuentra localizables, ordenados y resguardados | C26: 1
A27: SUBTOTAL POR DOMINIO: | C27: =SUM(C12:C26) -> 9
A28: II.- RECURSOS Y SUMINISTROS
A29: Cuenta con mecanismo de financiamiento para su operación | C29: 0
A30: Dispone de oficina para realizar actividades | C30: 0
A31: Cuenta con mobiliario y equipamiento para su funcionamiento | C31: 0
A32: Existen mecanismos para provisión de papeleria y demas insumos de oficina | C32: 0
A33: Dispone de un lugar para el resguardo de archivos o expedientes | C33: 0
A34: Cuenta con personal de apoyo administrativo | C34: 0
A35: SUBTOTAL POR DOMINIO: | C35: =SUM(C29:C34) -> 0
A36: III.- MARCO PROCEDIMENTAL
A37: Cuenta con reglamento interno para el funcionamiento del comité | C37: 0
A38: Cuenta con manual de organización del comité | C38: 0
A39: Cuenta con procedimiento para la solicitud de intervención en el análisis de casos o protocolos | C39: 0
A40: Cuenta con procedimiento para control y seguimiento de recomendaciones emitidas por el comité | C40: 0
A41: Cuenta con procedimiento para resguardo de la información | C41: 0
A42: Cuenta con procedimiento para sesiones oridnarias y extraordinarias | C42: 0
A43: Cuenta con procedimiento para comunicar recomendaciones | C43: 0
...

Sheet CHBISSSTE
A2: COMISIÓN DE BIOÉTICA DEL ESTADO DE TLAXCALA
A3: COMITÉS HOSPITALARIOS DE BIOÉTICA Y ÉTICA EN INVESTIGACIÓN
A4: CÉDULA DE VERIFICACIÓN
A5: Institución: | B5: Hospital General ISSSTE
A6: Responsable del establecimiento: | B6: Dr. Victor Hugo Pedraza Hernández
A7: Presidente o presidenta: | B7: LEI. Ilenny Alejandra Merchant Ortiz
A8: Fecha de visita: | B8: 45095
A9: Registro CONBIOÉTICA: | B9: No
A10: CRITERIOS DE VERIFICACIÓN
A11: I.- INTEGRACIÓN:
A12: Registro vigente ante la CONBIOÉTICA | C12: 0
A13: Acta de instalacion actualizada y vigente | C13: 1
A14: Cartas de designación por cada integrante | C14: 1
A15: Cartas de confidencialidad por cada integrante | C15: 1
A16: Cartas compromiso de capacitación por integrante | C16: 1
A17: Mínimo de miembros necesarios: presidente, vocal secretario y cuatro vocales | C17: 1
A18: Cumple con no incluir personal del cuerpo directivo | C18: 1
A19: Su conformación es multidisciplinaria | C19: 1
A20: En la integración incluye representante de la comunidad | C20: 1
A21: Expedientes actualizados por cada integrante: CV, copia de título, cédula y constancias de capacitación en bioética | C21: 0
A22: Existe equidad de género en la integración del comité | C22: 0
A23: Se hace uso de lenguaje incluyente en la documentación | C23: 0
... A26: Los documentos se encuentra localizables, ordenados y resguardados | C26: 0
A27: SUBTOTAL POR DOMINIO: | C27: =SUM(C12:C26) -> 10
A28: II.- RECURSOS Y SUMINISTROS
A29: Cuenta con mecanismo de financiamiento para su operación | C29: 0
A30: Dispone de oficina para realizar actividades | C30: 0
A31: Cuenta con mobiliario y equipamiento para su funcionamiento | C31: 0
A32: Existen mecanismos para provisión de papeleria y demas insumos de oficina | C32: 0
A33: Dispone de un lugar para el resguardo de archivos o expedientes | C33: 1
A34: Cuenta con personal de apoyo administrativo | C34: 0
A35: SUBTOTAL POR DOMINIO: | C35: =SUM(C29:C34) -> 1
A36: III.- MARCO PROCEDIMENTAL
A37: Cuenta con reglamento interno para el funcionamiento del comité | C37: 0
A38: Cuenta con manual de organización del comité | C38: 0
A39: Cuenta con procedimiento para la solicitud de intervención en el análisis de casos o protocolos | C39: 0
A40: Cuenta con procedimiento para control y seguimiento de recomendaciones emitidas por el comité | C40: 0
A41: Cuenta con procedimiento para resguardo de la información | C41: 0
A42: Cuenta con procedimiento para sesiones oridnarias y extraordinarias | C42: 0
A43: Cuenta con procedimiento para comunicar recomendaciones | C43: 0
...

Sheet CEIISSSTE
A2: COMISIÓN DE BIOÉTICA DEL ESTADO DE TLAXCALA
A3: COMITÉS HOSPITALARIOS DE BIOÉTICA Y ÉTICA EN INVESTIGACIÓN
A4: CÉDULA DE VERIFICACIÓN
A5: Institución: | B5: Hospital General ISSSTE
A6: Responsable del establecimiento: | B6: Dr. Victor Hugo Pedraza Hernández
A7: Presidente o presidenta: | B7: Dr. Carlos Arutor Jiménez Barreto
A8: Fecha de visita: | B8: 45491
A9: Registro CONBIOÉTICA: | B9: no
A10: CRITERIOS DE VERIFICACIÓN
A11: I.- INTEGRACIÓN:
A12: Registro vigente ante la CONBIOÉTICA | C12: 0
A13: Acta de instalacion actualizada y vigente | C13: 0
A14: Cartas de designación por cada integrante | C14: 0
A15: Cartas de confidencialidad por cada integrante | C15: 0
A16: Cartas compromiso de capacitación por integrante | C16: 0
A17: Mínimo de miembros necesarios: presidente, vocal secretario y cuatro vocales | C17: 0
A18: Cumple con no incluir personal del cuerpo directivo | C18: 0
A19: Su conformación es multidisciplinaria | C19: 0
A20: En la integración incluye representante de la comunidad | C20: 0
A21: Expedientes actualizados por cada integrante: CV, copia de título, cédula y constancias de capacitación en bioética | C21: 0
A22: Existe equidad de género en la integración del comité | C22: 0
A23: Se hace uso de lenguaje incluyente en la documentación | C23: 0
... A26: Los documentos se encuentra localizables, ordenados y resguardados | C26: 0
A27: SUBTOTAL POR DOMINIO: | C27: =SUM(C12:C26) -> 0
A28: II.- RECURSOS Y SUMINISTROS
A29: Cuenta con mecanismo de financiamiento para su operación | C29: 0
A30: Dispone de oficina para realizar actividades | C30: 0
A31: Cuenta con mobiliario y equipamiento para su funcionamiento | C31: 0
A32: Existen mecanismos para provisión de papeleria y demas insumos de oficina | C32: 0
A33: Dispone de un lugar para el resguardo de archivos o expedientes | C33: 0
A34: Cuenta con personal de apoyo administrativo | C34: 0
A35: SUBTOTAL POR DOMINIO: | C35: =SUM(C29:C34) -> 0
A36: III.- MARCO PROCEDIMENTAL
A37: Cuenta con reglamento interno para el funcionamiento del comité | C37: 0
A38: Cuenta con manual de organización del comité | C38: 0
A39: Cuenta con procedimiento para la solicitud de intervención en el análisis de casos o protocolos | C39: 0
A40: Cuenta con procedimiento para control y seguimiento de recomendaciones emitidas por el comité | C40: 0
A41: Cuenta con procedimiento para resguardo de la información | C41: 0
A42: Cuenta con procedimiento para sesiones oridnarias y extraordinarias | C42: 0
A43: Cuenta con procedimiento para comunicar recomendaciones | C43: 0
...

Sheet CHBIMSSZ2
A2: COMISIÓN DE BIOÉTICA DEL ESTADO DE TLAXCALA
A3: COMITÉS HOSPITALARIOS DE BIOÉTICA Y ÉTICA EN INVESTIGACIÓN
A4: CÉDULA DE VERIFICACIÓN
A5: Institución: | B5: Hospital General de Zona #2 IMSS
A6: Responsable del establecimiento: | B6: Dr. Ramon Muñoz Berruecos
A7: Presidente o presidenta: | B7: Dr. Miguel Angel Mendez de Leandro
A8: Fecha de visita: | B8: 45456
A9: Registro CONBIOÉTICA: | B9: NO
A10: CRITERIOS DE VERIFICACIÓN
A11: I.- INTEGRACIÓN:
A12: Registro vigente ante la CONBIOÉTICA | C12: 0
A13: Acta de instalacion actualizada y vigente | C13: 1
A14: Cartas de designación por cada integrante | C14: 1
A15: Cartas de confidencialidad por cada integrante | C15: 1
A16: Cartas compromiso de capacitación por integrante | C16: 1
A17: Mínimo de miembros necesarios: presidente, vocal secretario y cuatro vocales | C17: 1
A18: Cumple con no incluir personal del cuerpo directivo | C18: 0
A19: Su conformación es multidisciplinaria | C19: 1
A20: En la integración incluye representante de la comunidad | C20: 1
A21: Expedientes actualizados por cada integrante: CV, copia de título, cédula y constancias de capacitación en bioética | C21: 0
A22: Existe equidad de género en la integración del comité | C22: 0
A23: Se hace uso de lenguaje incluyente en la documentación | C23: 0
... A26: Los documentos se encuentra localizables, ordenados y resguardados | C26: 1
A27: SUBTOTAL POR DOMINIO: | C27: =SUM(C12:C26) -> 8
A28: II.- RECURSOS Y SUMINISTROS
A29: Cuenta con mecanismo de financiamiento para su operación | C29: 0
A30: Dispone de oficina para realizar actividades | C30: 1
A31: Cuenta con mobiliario y equipamiento para su funcionamiento | C31: 0
A32: Existen mecanismos para provisión de papeleria y demas insumos de oficina | C32: 0
A33: Dispone de un lugar para el resguardo de archivos o expedientes | C33: 0
A34: Cuenta con personal de apoyo administrativo | C34: 0
A35: SUBTOTAL POR DOMINIO: | C35: =SUM(C29:C34) -> 1
A36: III.- MARCO PROCEDIMENTAL
A37: Cuenta con reglamento interno para el funcionamiento del comité | C37: 0
A38: Cuenta con manual de organización del comité | C38: 0
A39: Cuenta con procedimiento para la solicitud de intervención en el análisis de casos o protocolos | C39: 0
A40: Cuenta con procedimiento para control y seguimiento de recomendaciones emitidas por el comité | C40: 0
A41: Cuenta con procedimiento para resguardo de la información | C41: 0
A42: Cuenta con procedimiento para sesiones oridnarias y extraordinarias | C42: 0
A43: Cuenta con procedimiento para comunicar recomendaciones | C43: 0
...

Sheet CEIOPDSeSa
A1: COMISIÓN DE BIOÉTICA DEL ESTADO DE TLAXCALA
A2: COMITÉS HOSPITALARIOS DE BIOÉTICA Y ÉTICA EN INVESTIGACIÓN
A3: CÉDULA DE VERIFICACIÓN
A4: Institución: | B4: OPD Salud De Tlaxcala
A5: Responsable del establecimiento: | B5: Rigoberto Zamudio Meneses
A6: Presidente o presidenta: | B6: Irma Alejandra Hernandez Vicente
A7: Fecha de visita: | B7: 45372
A8: Registro CONBIOÉTICA: | B8: 29-CEI-001-20220131
A9: CRITERIOS DE VERIFICACIÓN
A10: I.- INTEGRACIÓN:
A11: Registro vigente ante la CONBIOÉTICA | C11: 1
A12: Acta de instalacion actualizada y vigente | C12: 1
A13: Cartas de designación por cada integrante | C13: 1
A14: Cartas de confidencialidad por cada integrante | C14: 1
A15: Cartas compromiso de capacitación por integrante | C15: 1
A16: Mínimo de miembros necesarios: presidente, vocal secretario y cuatro vocales | C16: 1
A17: Cumple con no incluir personal del cuerpo directivo | C17: 1
A18: Su conformación es multidisciplinaria | C18: 1
A19: En la integración incluye representante de la comunidad | C19: 1
A20: Expedientes actualizados por cada integrante: CV, copia de título, cédula y constancias de capacitación en bioética | C20: 1
A21: Existe equidad de género en la integración del comité | C21: 1
A22: Se hace uso de lenguaje incluyente en la documentación | C22: 1
... A25: Los documentos se encuentra localizables, ordenados y resguardados | C25: 1
A26: SUBTOTAL POR DOMINIO: | C26: =SUM(C11:C25) -> 14
A27: II.- RECURSOS Y SUMINISTROS
A28: Cuenta con mecanismo de financiamiento para su operación | C28: 0
A29: Dispone de oficina para realizar actividades | C29: 0
A30: Cuenta con mobiliario y equipamiento para su funcionamiento | C30: 0
A31: Existen mecanismos para provisión de papeleria y demas insumos de oficina | C31: 0
A32: Dispone de un lugar para el resguardo de archivos o expedientes | C32: 0
A33: Cuenta con personal de apoyo administrativo | C33: 0
A34: SUBTOTAL POR DOMINIO: | C34: =SUM(C28:C33) -> 0
A35: III.- MARCO PROCEDIMENTAL
A36: Cuenta con reglamento interno para el funcionamiento del comité | C36: 1
A37: Cuenta con manual de organización del comité | C37: 1
A38: Cuenta con procedimiento para la solicitud de intervención en el análisis de casos o protocolos | C38: 0
A39: Cuenta con procedimiento para control y seguimiento de recomendaciones emitidas por el comité | C39: 1
A40: Cuenta con procedimiento para resguardo de la información | C40: 0
A41: Cuenta con procedimiento para sesiones oridnarias y extraordinarias | C41: 1
A42: Cuenta con procedimiento para comunicar recomendaciones | C42: 1
...

Sheet CHBHIT
A1: COMISIÓN DE BIOÉTICA DEL ESTADO DE TLAXCALA
A2: COMITÉS HOSPITALARIOS DE BIOÉTICA Y ÉTICA EN INVESTIGACIÓN
A3: CÉDULA DE VERIFICACIÓN
A4: Institución: | B4: Hospital Infanitl de Tlaxcala
A5: Responsable del establecimiento: | B5: Daniel Romero Lopez
A6: Presidente o presidenta: | B6: Carlos Manuel Vinay Prado
A7: Fecha de visita: | B7: 45365
A8: Registro CONBIOÉTICA: | B8: 29CHB00120130322
A9: CRITERIOS DE VERIFICACIÓN
A10: I.- INTEGRACIÓN:
A11: Registro vigente ante la CONBIOÉTICA | C11: 1
A12: Acta de instalacion actualizada y vigente | C12: 0
A13: Cartas de designación por cada integrante | C13: 1
A14: Cartas de confidencialidad por cada integrante | C14: 1
A15: Cartas compromiso de capacitación por integrante | C15: 1
A16: Mínimo de miembros necesarios: presidente, vocal secretario y cuatro vocales | C16: 1
A17: Cumple con no incluir personal del cuerpo directivo | C17: 1
A18: Su conformación es multidisciplinaria | C18: 1
A19: En la integración incluye representante de la comunidad | C19: 0
A20: Expedientes actualizados por cada integrante: CV, copia de título, cédula y constancias de capacitación en bioética | C20: 0
A21: Existe equidad de género en la integración del comité | C21: 0
A22: Se hace uso de lenguaje incluyente en la documentación | C22: 0
... A25: Los documentos se encuentra localizables, ordenados y resguardados | C25: 1
A26: SUBTOTAL POR DOMINIO: | C26: =SUM(C11:C25) -> 10
A27: II.- RECURSOS Y SUMINISTROS
A28: Cuenta con mecanismo de financiamiento para su operación | C28: 0
A29: Dispone de oficina para realizar actividades | C29: 0
A30: Cuenta con mobiliario y equipamiento para su funcionamiento | C30: 0
A31: Existen mecanismos para provisión de papeleria y demas insumos de oficina | C31: 0
A32: Dispone de un lugar para el resguardo de archivos o expedientes | C32: 0
A33: Cuenta con personal de apoyo administrativo | C33: 0
A34: SUBTOTAL POR DOMINIO: | C34: =SUM(C28:C33) -> 0
A35: III.- MARCO PROCEDIMENTAL
A36: Cuenta con reglamento interno para el funcionamiento del comité | C36: 1
A37: Cuenta con manual de organización del comité | C37: 1
A38: Cuenta con procedimiento para la solicitud de intervención en el análisis de casos o protocolos | C38: 1
A39: Cuenta con procedimiento para control y seguimiento de recomendaciones emitidas por el comité | C39: 1
A40: Cuenta con procedimiento para resguardo de la información | C40: 1
A41: Cuenta con procedimiento para sesiones oridnarias y extraordinarias | C41: 1
A42: Cuenta con procedimiento para comunicar recomendaciones | C42: 1
...

Sheet CEIHIT
A1: COMISIÓN DE BIOÉTICA DEL ESTADO DE TLAXCALA
A2: COMITÉS HOSPITALARIOS DE BIOÉTICA Y ÉTICA EN INVESTIGACIÓN
A3: CÉDULA DE VERIFICACIÓN
A4: Institución: | B4: Hospital Infanti de Tlaxcala
A5: Responsable del establecimiento: | B5: Daniel Romero Lopez
A6: Presidente o presidenta: | B6: Victor Manuel Gomez Juarez
A7: Fecha de visita: | B7: 45365
A8: Registro CONBIOÉTICA: | B8: No
A9: CRITERIOS DE VERIFICACIÓN
A10: I.- INTEGRACIÓN:
A11: Registro vigente ante la CONBIOÉTICA | C11: 0
A12: Acta de instalacion actualizada y vigente | C12: 0
A13: Cartas de designación por cada integrante | C13: 0
A14: Cartas de confidencialidad por cada integrante | C14: 0
A15: Cartas compromiso de capacitación por integrante | C15: 0
A16: Mínimo de miembros necesarios: presidente, vocal secretario y cuatro vocales | C16: 0
A17: Cumple con no incluir personal del cuerpo directivo | C17: 0
A18: Su conformación es multidisciplinaria | C18: 1
A19: En la integración incluye representante de la comunidad | C19: 1
A20: Expedientes actualizados por cada integrante: CV, copia de título, cédula y constancias de capacitación en bioética | C20: 1
A21: Existe equidad de género en la integración del comité | C21: 0
A22: Se hace uso de lenguaje incluyente en la documentación | C22: 0
... A25: Los documentos se encuentra localizables, ordenados y resguardados | C25: 0
A26: SUBTOTAL POR DOMINIO, 15 PUNTOS, 35%: | C26: =SUM(C11:C25) -> 5
A27: II.- RECURSOS Y SUMINISTROS
A28: Cuenta con mecanismo de financiamiento para su operación | C28: 0
A29: Dispone de oficina para realizar actividades | C29: 1
A30: Cuenta con mobiliario y equipamiento para su funcionamiento | C30: 0
A31: Existen mecanismos para provisión de papeleria y demas insumos de oficina | C31: 0
A32: Dispone de un lugar para el resguardo de archivos o expedientes | C32: 0
A33: Cuenta con personal de apoyo administrativo | C33: 0
A34: SUBTOTAL POR DOMINIO, 5 PUNTOS, 12%: | C34: =SUM(C28:C33) -> 1
A35: III.- MARCO PROCEDIMENTAL
A36: Cuenta con reglamento interno para el funcionamiento del comité | C36: 0
A37: Cuenta con manual de organización del comité | C37: 0
A38: Cuenta con procedimiento para la solicitud de intervención en el análisis de casos o protocolos | C38: 0
A39: Cuenta con procedimiento para control y seguimiento de recomendaciones emitidas por el comité | C39: 0
A40: Cuenta con procedimiento para resguardo de la información | C40: 0
A41: Cuenta con procedimiento para sesiones oridnarias y extraordinarias | C41: 0
A42: Cuenta con procedimiento para comunicar recomendaciones | C42: 0
...

Sheet CHBHuamantla
A2: COMISIÓN DE BIOÉTICA DEL ESTADO DE TLAXCALA
A3: COMITÉS HOSPITALARIOS DE BIOÉTICA Y ÉTICA EN INVESTIGACIÓN
A4: CÉDULA DE VERIFICACIÓN
A5: Institución: | B5: Hospital General de Humantla
A6: Responsable del establecimiento: | B6: Alejandro Alvarado Gonzalez
A7: Presidente o presidenta: | B7: Lucia Flores Cortéz
A8: Fecha de visita: | B8: 45436
A9: Registro CONBIOÉTICA: | B9: No
A10: CRITERIOS DE VERIFICACIÓN
A11: I.- INTEGRACIÓN:
A12: Registro vigente ante la CONBIOÉTICA | C12: 0
A13: Acta de instalacion actualizada y vigente | C13: 0
A14: Cartas de designación por cada integrante | C14: 0
A15: Cartas de confidencialidad por cada integrante | C15: 0
A16: Cartas compromiso de capacitación por integrante | C16: 0
A17: Mínimo de miembros necesarios: presidente, vocal secretario y cuatro vocales | C17: 1
A18: Cumple con no incluir personal del cuerpo directivo | C18: 1
A19: Su conformación es multidisciplinaria | C19: 1
A20: En la integración incluye representante de la comunidad | C20: 1
A21: Expedientes actualizados por cada integrante: CV, copia de título, cédula y constancias de capacitación en bioética | C21: 0
A22: Existe equidad de género en la integración del comité | C22: 0
A23: Se hace uso de lenguaje incluyente en la documentación | C23: 0
... A26: Los documentos se encuentra localizables, ordenados y resguardados | C26: 1
A27: SUBTOTAL POR DOMINIO, 15 PUNTOS, 35%: | C27: =SUM(C12:C26) -> 7
A28: II.- RECURSOS Y SUMINISTROS
A29: Cuenta con mecanismo de financiamiento para su operación | C29: 0
A30: Dispone de oficina para realizar actividades | C30: 1
A31: Cuenta con mobiliario y equipamiento para su funcionamiento | C31: 1
A32: Existen mecanismos para provisión de papeleria y demas insumos de oficina | C32: 1
A33: Dispone de un lugar para el resguardo de archivos o expedientes | C33: 1
A34: Cuenta con personal de apoyo administrativo | C34: 0
A35: SUBTOTAL POR DOMINIO, 5 PUNTOS, 12%: | C35: =SUM(C29:C34) -> 4
A36: III.- MARCO PROCEDIMENTAL
A37: Cuenta con reglamento interno para el funcionamiento del comité | C37: 0
A38: Cuenta con manual de organización del comité | C38: 0
A39: Cuenta con procedimiento para la solicitud de intervención en el análisis de casos o protocolos | C39: 0
A40: Cuenta con procedimiento para control y seguimiento de recomendaciones emitidas por el comité | C40: 0
A41: Cuenta con procedimiento para resguardo de la información | C41: 0
A42: Cuenta con procedimiento para sesiones oridnarias y extraordinarias | C42: 0
A43: Cuenta con procedimiento para comunicar recomendaciones | C43: 0
...

Sheet CHBHumanitas
A2: COMISIÓN DE BIOÉTICA DEL ESTADO DE TLAXCALA
A3: COMITÉS HOSPITALARIOS DE BIOÉTICA Y ÉTICA EN INVESTIGACIÓN
A4: CÉDULA DE VERIFICACIÓN
A5: Institución: | B5: Hospital Humanitas de Tlaxcala
A6: Responsable del establecimiento: | B6: Dr. Jaime Tizatl juarez
A7: Presidente o presidenta: | B7: Dra. Saray Munive Hernández
A8: Fecha de visita: | B8: 45448
A9: Registro CONBIOÉTICA: | B9: SI
A10: CRITERIOS DE VERIFICACIÓN
A11: I.- INTEGRACIÓN:
A12: Registro vigente ante la CONBIOÉTICA | C12: 1
A13: Acta de instalacion actualizada y vigente | C13: 0
A14: Cartas de designación por cada integrante | C14: 1
A15: Cartas de confidencialidad por cada integrante | C15: 1
A16: Cartas compromiso de capacitación por integrante | C16: 0
A17: Mínimo de miembros necesarios: presidente, vocal secretario y cuatro vocales | C17: 0
A18: Cumple con no incluir personal del cuerpo directivo | C18: 1
A19: Su conformación es multidisciplinaria | C19: 1
A20: En la integración incluye representante de la comunidad | C20: 0
A21: Expedientes actualizados por cada integrante: CV, copia de título, cédula y constancias de capacitación en bioética | C21: 0
A22: Existe equidad de género en la integración del comité | C22: 0
A23: Se hace uso de lenguaje incluyente en la documentación | C23: 0
... A26: Los documentos se encuentra localizables, ordenados y resguardados | C26: 1
A27: SUBTOTAL POR DOMINIO, 15 PUNTOS, 35%: | C27: =SUM(C12:C26) -> 7
A28: II.- RECURSOS Y SUMINISTROS
A29: Cuenta con mecanismo de financiamiento para su operación | C29: 0
A30: Dispone de oficina para realizar actividades | C30: 1
A31: Cuenta con mobiliario y equipamiento para su funcionamiento | C31: 1
A32: Existen mecanismos para provisión de papeleria y demas insumos de oficina | C32: 1
A33: Dispone de un lugar para el resguardo de archivos o expedientes | C33: 1
A34: Cuenta con personal de apoyo administrativo | C34: 0
A35: SUBTOTAL POR DOMINIO, 5 PUNTOS, 12%: | C35: =SUM(C29:C34) -> 4
A36: III.- MARCO PROCEDIMENTAL
A37: Cuenta con reglamento interno para el funcionamiento del comité | C37: 0
A38: Cuenta con manual de organización del comité | C38: 0
A39: Cuenta con procedimiento para la solicitud de intervención en el análisis de casos o protocolos | C39: 0
A40: Cuenta con procedimiento para control y seguimiento de recomendaciones emitidas por el comité | C40: 0
A41: Cuenta con procedimiento para resguardo de la información | C41: 0
A42: Cuenta con procedimiento para sesiones oridnarias y extraordinarias | C42: 0
A43: Cuenta con procedimiento para comunicar recomendaciones | C43: 0
...

Sheet CHBHCalpulalpan
A2: COMISIÓN DE BIOÉTICA DEL ESTADO DE TLAXCALA
A3: COMITÉS HOSPITALARIOS DE BIOÉTICA Y ÉTICA EN INVESTIGACIÓN
A4: CÉDULA DE VERIFICACIÓN
A5: Institución: | B5: Hospital General de Calpulapan
A6: Responsable del establecimiento: | B6: Dr. Oscar Arturo Langarrica Monterrubio
A7: Presidente o presidenta: | B7: Dr. Oscar Saldaña Manzano
A8: Fecha de visita: | B8: 45610
A9: Registro CONBIOÉTICA: | B9: No
A10: CRITERIOS DE VERIFICACIÓN
A11: I.- INTEGRACIÓN:
A12: Registro vigente ante la CONBIOÉTICA | C12: 0
A13: Acta de instalacion actualizada y vigente | C13: 0
A14: Cartas de designación por cada integrante | C14: 1
A15: Cartas de confidencialidad por cada integrante | C15: 1
A16: Cartas compromiso de capacitación por integrante | C16: 0
A17: Mínimo de miembros necesarios: presidente, vocal secretario y cuatro vocales | C17: 0
A18: Cumple con no incluir personal del cuerpo directivo | C18: 1
A19: Su conformación es multidisciplinaria | C19: 1
A20: En la integración incluye representante de la comunidad | C20: 1
A21: Expedientes actualizados por cada integrante: CV, copia de título, cédula y constancias de capacitación en bioética | C21: 1
A22: Existe equidad de género en la integración del comité | C22: 0
A23: Se hace uso de lenguaje incluyente en la documentación | C23: 0
... A26: Los documentos se encuentra localizables, ordenados y resguardados | C26: 1
A27: SUBTOTAL POR DOMINIO, 15 PUNTOS, 35%: | C27: =SUM(C12:C26) -> 8
A28: II.- RECURSOS Y SUMINISTROS
A29: Cuenta con mecanismo de financiamiento para su operación | C29: 0
A30: Dispone de oficina para realizar actividades | C30: 0
A31: Cuenta con mobiliario y equipamiento para su funcionamiento | C31: 0
A32: Existen mecanismos para provisión de papeleria y demas insumos de oficina | C32: 0
A33: Dispone de un lugar para el resguardo de archivos o expedientes | C33: 0
A34: Cuenta con personal de apoyo administrativo | C34: 0
A35: SUBTOTAL POR DOMINIO, 5 PUNTOS, 12%: | C35: =SUM(C29:C34) -> 0
A36: III.- MARCO PROCEDIMENTAL
A37: Cuenta con reglamento interno para el funcionamiento del comité | C37: 0
A38: Cuenta con manual de organización del comité | C38: 0
A39: Cuenta con procedimiento para la solicitud de intervención en el análisis de casos o protocolos | C39: 0
A40: Cuenta con procedimiento para control y seguimiento de recomendaciones emitidas por el comité | C40: 0
A41: Cuenta con procedimiento para resguardo de la información | C41: 0
A42: Cuenta con procedimiento para sesiones oridnarias y extraordinarias | C42: 0
A43: Cuenta con procedimiento para comunicar recomendaciones | C43: 0
...

Sheet CHBHGT
A2: COMISIÓN DE BIOÉTICA DEL ESTADO DE TLAXCALA
A3: COMITÉS HOSPITALARIOS DE BIOÉTICA Y ÉTICA EN INVESTIGACIÓN
A4: CÉDULA DE VERIFICACIÓN
A5: Institución: | B5: Hospital General de Tlaxcala
A6: Responsable del establecimiento: | B6: Dra. Sofia Romero Hernández
A7: Presidente o presidenta: | B7: Dra. Nancy Estrada Paez
A8: Fecha de visita: | B8: 45449
A9: Registro CONBIOÉTICA: | B9: No
A10: CRITERIOS DE VERIFICACIÓN
A11: I.- INTEGRACIÓN:
A12: Registro vigente ante la CONBIOÉTICA | C12: 0
A13: Acta de instalacion actualizada y vigente | C13: 0
A14: Cartas de designación por cada integrante | C14: 0
A15: Cartas de confidencialidad por cada integrante | C15: 0
A16: Cartas compromiso de capacitación por integrante | C16: 0
A17: Mínimo de miembros necesarios: presidente, vocal secretario y cuatro vocales | C17: 1
A18: Cumple con no incluir personal del cuerpo directivo | C18: 0
A19: Su conformación es multidisciplinaria | C19: 1
A20: En la integración incluye representante de la comunidad | C20: 1
A21: Expedientes actualizados por cada integrante: CV, copia de título, cédula y constancias de capacitación en bioética | C21: 1
A22: Existe equidad de género en la integración del comité | C22: 0
A23: Se hace uso de lenguaje incluyente en la documentación | C23: 0
... A26: Los documentos se encuentra localizables, ordenados y resguardados | C26: 1
A27: SUBTOTAL POR DOMINIO, 15 PUNTOS, 35%: | C27: =SUM(C12:C26) -> 5
A28: II.- RECURSOS Y SUMINISTROS
A29: Cuenta con mecanismo de financiamiento para su operación | C29: 0
A30: Dispone de oficina para realizar actividades | C30: 1
A31: Cuenta con mobiliario y equipamiento para su funcionamiento | C31: 1
A32: Existen mecanismos para provisión de papeleria y demas insumos de oficina | C32: 1
A33: Dispone de un lugar para el resguardo de archivos o expedientes | C33: 1
A34: Cuenta con personal de apoyo administrativo | C34: 0
A35: SUBTOTAL POR DOMINIO, 5 PUNTOS, 12%: | C35: =SUM(C29:C34) -> 4
A36: III.- MARCO PROCEDIMENTAL
A37: Cuenta con reglamento interno para el funcionamiento del comité | C37: 0
A38: Cuenta con manual de organización del comité | C38: 0
A39: Cuenta con procedimiento para la solicitud de intervención en el análisis de casos o protocolos | C39: 0
A40: Cuenta con procedimiento para control y seguimiento de recomendaciones emitidas por el comité | C40: 0
A41: Cuenta con procedimiento para resguardo de la información | C41: 0
A42: Cuenta con procedimiento para sesiones oridnarias y extraordinarias | C42: 0
A43: Cuenta con procedimiento para comunicar recomendaciones | C43: 0
...

Sheet CEIHGT
A2: COMISIÓN DE BIOÉTICA DEL ESTADO DE TLAXCALA
A3: COMITÉS HOSPITALARIOS DE BIOÉTICA Y ÉTICA EN INVESTIGACIÓN
A4: CÉDULA DE VERIFICACIÓN
A5: Institución: | B5: Hospital General de Tlaxcala
A6: Responsable del establecimiento: | B6: Dra. Sofia Romero Hernández
A7: Presidente o presidenta: | B7: Dr. Pablo Mendez Hernandez
A8: Fecha de visita: | B8: 45450
A9: Registro CONBIOÉTICA: | B9: No
A10: CRITERIOS DE VERIFICACIÓN
A11: I.- INTEGRACIÓN:
A12: Registro vigente ante la CONBIOÉTICA | C12: 0
A13: Acta de instalacion actualizada y vigente | C13: 0
A14: Cartas de designación por cada integrante | C14: 0
A15: Cartas de confidencialidad por cada integrante | C15: 0
A16: Cartas compromiso de capacitación por integrante | C16: 0
A17: Mínimo de miembros necesarios: presidente, vocal secretario y cuatro vocales | C17: 1
A18: Cumple con no incluir personal del cuerpo directivo | C18: 1
A19: Su conformación es multidisciplinaria | C19: 1
A20: En la integración incluye representante de la comunidad | C20: 0
A21: Expedientes actualizados por cada integrante: CV, copia de título, cédula y constancias de capacitación en bioética | C21: 0
A22: Existe equidad de género en la integración del comité | C22: 0
A23: Se hace uso de lenguaje incluyente en la documentación | C23: 0
... A26: Los documentos se encuentra localizables, ordenados y resguardados | C26: 0
A27: SUBTOTAL POR DOMINIO, 15 PUNTOS, 35%: | C27: =SUM(C12:C26) -> 3
A28: II.- RECURSOS Y SUMINISTROS
A29: Cuenta con mecanismo de financiamiento para su operación | C29: 0
A30: Dispone de oficina para realizar actividades | C30: 1
A31: Cuenta con mobiliario y equipamiento para su funcionamiento | C31: 1
A32: Existen mecanismos para provisión de papeleria y demas insumos de oficina | C32: 1
A33: Dispone de un lugar para el resguardo de archivos o expedientes | C33: 1
A34: Cuenta con personal de apoyo administrativo | C34: 0
A35: SUBTOTAL POR DOMINIO, 5 PUNTOS, 12%: | C35: =SUM(C29:C34) -> 4
A36: III.- MARCO PROCEDIMENTAL
A37: Cuenta con reglamento interno para el funcionamiento del comité | C37: 0
A38: Cuenta con manual de organización del comité | C38: 0
A39: Cuenta con procedimiento para la solicitud de intervención en el análisis de casos o protocolos | C39: 0
A40: Cuenta con procedimiento para control y seguimiento de recomendaciones emitidas por el comité | C40: 0
A41: Cuenta con procedimiento para resguardo de la información | C41: 0
A42: Cuenta con procedimiento para sesiones oridnarias y extraordinarias | C42: 0
A43: Cuenta con procedimiento para comunicar recomendaciones | C43: 0
...

Sheet CHBHRESP
A2: COMISIÓN DE BIOÉTICA DEL ESTADO DE TLAXCALA
A3: COMITÉS HOSPITALARIOS DE BIOÉTICA Y ÉTICA EN INVESTIGACIÓN
A4: CÉDULA DE VERIFICACIÓN
A5: Institución: | B5: HOSPITAL REGIONAL DE APIZACO ESP
A6: Responsable del establecimiento: | B6: Dr. Miguel Angel Xolocotzi Juárez
A7: Presidente o presidenta: | B7: Mtra. Silvia Degante Huerta
A8: Fecha de visita: | B8: 45454
A9: Registro CONBIOÉTICA: | B9: No
A10: CRITERIOS DE VERIFICACIÓN
A11: I.- INTEGRACIÓN:
A12: Registro vigente ante la CONBIOÉTICA | C12: 0
A13: Acta de instalacion actualizada y vigente | C13: 1
A14: Cartas de designación por cada integrante | C14: 1
A15: Cartas de confidencialidad por cada integrante | C15: 0
A16: Cartas compromiso de capacitación por integrante | C16: 0
A17: Mínimo de miembros necesarios: presidente, vocal secretario y cuatro vocales | C17: 1
A18: Cumple con no incluir personal del cuerpo directivo | C18: 1
A19: Su conformación es multidisciplinaria | C19: 1
A20: En la integración incluye representante de la comunidad | C20: 1
A21: Expedientes actualizados por cada integrante: CV, copia de título, cédula y constancias de capacitación en bioética | C21: 0
A22: Existe equidad de género en la integración del comité | C22: 0
A23: Se hace uso de lenguaje incluyente en la documentación | C23: 0
... A26: Los documentos se encuentra localizables, ordenados y resguardados | C26: 1
A27: SUBTOTAL POR DOMINIO, 15 PUNTOS, 35%: | C27: =SUM(C12:C26) -> 9
A28: II.- RECURSOS Y SUMINISTROS
A29: Cuenta con mecanismo de financiamiento para su operación | C29: 0
A30: Dispone de oficina para realizar actividades | C30: 0
A31: Cuenta con mobiliario y equipamiento para su funcionamiento | C31: 0
A32: Existen mecanismos para provisión de papeleria y demas insumos de oficina | C32: 0
A33: Dispone de un lugar para el resguardo de archivos o expedientes | C33: 0
A34: Cuenta con personal de apoyo administrativo | C34: 0
A35: SUBTOTAL POR DOMINIO, 5 PUNTOS, 12%: | C35: =SUM(C29:C34) -> 0
A36: III.- MARCO PROCEDIMENTAL
A37: Cuenta con reglamento interno para el funcionamiento del comité | C37: 0
A38: Cuenta con manual de organización del comité | C38: 0
A39: Cuenta con procedimiento para la solicitud de intervención en el análisis de casos o protocolos | C39: 0
A40: Cuenta con procedimiento para control y seguimiento de recomendaciones emitidas por el comité | C40: 0
A41: Cuenta con procedimiento para resguardo de la información | C41: 0
A42: Cuenta con procedimiento para sesiones oridnarias y extraordinarias | C42: 0
A43: Cuenta con procedimiento para comunicar recomendaciones | C43: 0
...

Sheet SUPERVISIONES2024
A2: COMISIÓN DE BIOÉTICA DEL ESTADO DE TLAXCALA
A3: COMITÉS HOSPITALARIOS DE BIOÉTICA Y ÉTICA EN INVESTIGACIÓN
A4: CONCENTRADO DE RESULTADOS
A5: CRITERIOS DE VERIFICACIÓN
A6: I.- INTEGRACIÓN:
A7: Registro vigente ante la CONBIOÉTICA | C7: =SUM(CEIOPDSeSa!C11+CHBHIT!C11+CEIHIT!C11) -> 2
A8: Acta de instalacion actualizada y vigente | C8: =(CEIOPDSeSa!C12+CHBHIT!C12+CEIHIT!C12) -> 1
A9: Cartas de designación por cada integrante | C9: =(CEIOPDSeSa!C13+CHBHIT!C13+CEIHIT!C13) -> 2
A10: Cartas de confidencialidad por cada integrante | C10: =(CEIOPDSeSa!C14+CHBHIT!C14+CEIHIT!C14) -> 2
A11: Cartas compromiso de capacitación por integrante | C11: =(CEIOPDSeSa!C15+CHBHIT!C15+CEIHIT!C15) -> 2
A12: Mínimo de miembros necesarios: presidente, vocal secretario y cuatro vocales | C12: =(CEIOPDSeSa!C16+CHBHIT!C16+CEIHIT!C16) -> 2
A13: Cumple con no incluir personal del cuerpo directivo | C13: =(CEIOPDSeSa!C17+CHBHIT!C17+CEIHIT!C17) -> 2
A14: Su conformación es multidisciplinaria | C14: =(CEIOPDSeSa!C18+CHBHIT!C18+CEIHIT!C18) -> 3
A15: En la integración incluye representante de la comunidad | C15: =(CEIOPDSeSa!C19+CHBHIT!C19+CEIHIT!C19) -> 2
A16: Expedientes actualizados por cada integrante: CV, copia de título, cédula y constancias de capacitación en bioética | C16: =(CEIOPDSeSa!C20+CHBHIT!C20+CEIHIT!C20) -> 2
A17: Existe equidad de género en la integración del comité | C17: =(CEIOPDSeSa!C21+CHBHIT!C21+CEIHIT!C21) -> 1
A18: Se hace uso de lenguaje incluyente en la documentación | C18: =(CEIOPDSeSa!C22+CHBHIT!C22+CEIHIT!C22) -> 1
A19: Al menos dos integrantes tienen formación bioética | C19: =(CEIOPDSeSa!C23+CHBHIT!C23+CEIHIT!C23) -> 3
... A21: Los documentos se encuentra localizables, ordenados y resguardados | C21: =(CEIOPDSeSa!C25+CHBHIT!C25+CEIHIT!C25) -> 2
A22: SUBTOTAL POR DOMINIO: | C22: =SUM(C7:C21) -> 29
A23: II.- RECURSOS Y SUMINISTROS
A24: Cuenta con mecanismo de financiamiento para su operación | C24: =(CEIOPDSeSa!C28+CHBHIT!C28+CEIHIT!C28) -> 0
A25: Dispone de oficina para realizar actividades | C25: =(CEIOPDSeSa!C29+CHBHIT!C29+CEIHIT!C29) -> 1
A26: Cuenta con mobiliario y equipamiento para su funcionamiento | C26: =(CEIOPDSeSa!C30+CHBHIT!C30+CEIHIT!C30) -> 0
A27: Existen mecanismos para provisión de papeleria y demas insumos de oficina | C27: =(CEIOPDSeSa!C31+CHBHIT!C31+CEIHIT!C31) -> 0
A28: Dispone de un lugar para el resguardo de archivos o expedientes | C28: =(CEIOPDSeSa!C32+CHBHIT!C32+CEIHIT!C32) -> 0
A29: Cuenta con personal de apoyo administrativo | C29: =(CEIOPDSeSa!C33+CHBHIT!C33+CEIHIT!C33) -> 0
A30: SUBTOTAL POR DOMINIO: | C30: =SUM(C24:C29) -> 1
A31: III.- MARCO PROCEDIMENTAL
A32: Cuenta con reglamento interno para el funcionamiento del comité | C32: =(CEIOPDSeSa!C36+CHBHIT!C36+CEIHIT!C36) -> 2
A33: Cuenta con manual de organización del comité | C33: =(CEIOPDSeSa!C37+CHBHIT!C37+CEIHIT!C37) -> 2
A34: Cuenta con procedimiento para la solicitud de intervención en el análisis de casos o protocolos | C34: =(CEIOPDSeSa!C38+CHBHIT!C38+CEIHIT!C38) -> 1
A35: Cuenta con procedimiento para control y seguimiento de recomendaciones emitidas por el comité | C35: =(CEIOPDSeSa!C39+CHBHIT!C39+CEIHIT!C39) -> 2
A36: Cuenta con procedimiento para resguardo de la información | C36: =(CEIOPDSeSa!C40+CHBHIT!C40+CEIHIT!C40) -> 1
A37: Cuenta con procedimiento para sesiones oridnarias y extraordinarias | C37: =(CEIOPDSeSa!C41+CHBHIT!C41+CEIHIT!C41) -> 2
